Traceback (most recent call last):
  File "C:\Users\user\AppData\Local\Programs\Python\Python311\Lib\site-packages\jupyter_cache\executors\utils.py", line 58, in single_nb_execution
    executenb(
  File "C:\Users\user\AppData\Local\Programs\Python\Python311\Lib\site-packages\nbclient\client.py", line 1314, in execute
    return NotebookClient(nb=nb, resources=resources, km=km, **kwargs).execute()
           ^^^^^^^^^^^^^^^^^^^^^^^^^^^^^^^^^^^^^^^^^^^^^^^^^^^^^^^^^^^^^^^^^^^^^
  File "C:\Users\user\AppData\Local\Programs\Python\Python311\Lib\site-packages\jupyter_core\utils\__init__.py", line 165, in wrapped
    return loop.run_until_complete(inner)
           ^^^^^^^^^^^^^^^^^^^^^^^^^^^^^^
  File "C:\Users\user\AppData\Local\Programs\Python\Python311\Lib\asyncio\base_events.py", line 653, in run_until_complete
    return future.result()
           ^^^^^^^^^^^^^^^
  File "C:\Users\user\AppData\Local\Programs\Python\Python311\Lib\site-packages\nbclient\client.py", line 709, in async_execute
    await self.async_execute_cell(
  File "C:\Users\user\AppData\Local\Programs\Python\Python311\Lib\site-packages\nbclient\client.py", line 1062, in async_execute_cell
    await self._check_raise_for_error(cell, cell_index, exec_reply)
  File "C:\Users\user\AppData\Local\Programs\Python\Python311\Lib\site-packages\nbclient\client.py", line 918, in _check_raise_for_error
    raise CellExecutionError.from_cell_and_msg(cell, exec_reply_content)
nbclient.exceptions.CellExecutionError: An error occurred while executing the following cell:
------------------
import matplotlib.pyplot as plt
import seaborn as sns

fig, ax1 = plt.subplots(figsize=(16, 8))
plt.title("Jumlah Penumpang Kereta Api", fontsize=24)
plt.ylabel('Jumlah Penumpang', fontsize=18)
plt.xlabel('Tahun', fontsize=18)
sns.set_palette(["#090364", "#1960EF", "#EF5919"])
sns.lineplot(data=df['PassengerCount'], linewidth=1.0, dashes=False, ax=ax1)
plt.show()
------------------


[1;31m---------------------------------------------------------------------------[0m
[1;31mModuleNotFoundError[0m                       Traceback (most recent call last)
Cell [1;32mIn[3], line 2[0m
[0;32m      1[0m [38;5;28;01mimport[39;00m [38;5;21;01mmatplotlib[39;00m[38;5;21;01m.[39;00m[38;5;21;01mpyplot[39;00m [38;5;28;01mas[39;00m [38;5;21;01mplt[39;00m
[1;32m----> 2[0m [38;5;28;01mimport[39;00m [38;5;21;01mseaborn[39;00m [38;5;28;01mas[39;00m [38;5;21;01msns[39;00m
[0;32m      4[0m fig, ax1 [38;5;241m=[39m plt[38;5;241m.[39msubplots(figsize[38;5;241m=[39m([38;5;241m16[39m, [38;5;241m8[39m))
[0;32m      5[0m plt[38;5;241m.[39mtitle([38;5;124m"[39m[38;5;124mJumlah Penumpang Kereta Api[39m[38;5;124m"[39m, fontsize[38;5;241m=[39m[38;5;241m24[39m)

[1;31mModuleNotFoundError[0m: No module named 'seaborn'

